<mujoco model="draw_arm">
  <compiler angle="radian" coordinate="local" inertiafromgeom="true"/>

  <!--
    Stability-oriented model:
    - implicitfast integrator for better stability with stiff control.
    - Disable collisions by default to avoid self-collision near joints.
      (This demo draws virtually; pen-down is detected from the slide joint.)
  -->
  <option timestep="0.002" gravity="0 0 -9.81" integrator="implicitfast"/>
  <size njmax="2000" nconmax="2000"/>

  <default>
    <!-- disable collision by default -->
    <geom contype="0" conaffinity="0" density="300"/>
    <joint damping="1" frictionloss="0.05"/>
  </default>

  <asset>
    <texture name="grid" type="2d" builtin="checker"
             rgb1="0.90 0.90 0.90" rgb2="0.97 0.97 0.97"
             width="256" height="256"/>
    <material name="mat_canvas" texture="grid" texrepeat="6 6" rgba="1 1 1 1"/>
  </asset>

  <worldbody>
    <!-- Visual canvas (non-colliding) -->
    <body name="table" pos="0 0 0">
      <geom name="canvas" type="box" size="0.25 0.18 0.005"
            pos="0.23 0 -0.005" material="mat_canvas" rgba="1 1 1 1"
            contype="0" conaffinity="0"/>
    </body>

    <!-- Planar 3-link arm -->
    <body name="base" pos="0 0 0.12">
      <geom name="base_geom" type="cylinder" size="0.03 0.02" rgba="0.30 0.30 0.30 1"/>

      <body name="link1" pos="0 0 0">
        <joint name="shoulder" type="hinge" axis="0 0 1"
               limited="true" range="-3.1416 3.1416"/>
        <geom name="link1_geom" type="capsule" fromto="0 0 0 0.20 0 0"
              size="0.018" rgba="0.90 0.20 0.20 1"/>

        <body name="link2" pos="0.20 0 0">
          <joint name="elbow" type="hinge" axis="0 0 1"
                 limited="true" range="-3.1416 3.1416"/>
          <geom name="link2_geom" type="capsule" fromto="0 0 0 0.20 0 0"
                size="0.016" rgba="0.20 0.90 0.20 1"/>

          <body name="link3" pos="0.20 0 0">
            <joint name="wrist" type="hinge" axis="0 0 1" damping="0.6"
                   limited="true" range="-3.1416 3.1416"/>
            <geom name="link3_geom" type="capsule" fromto="0 0 0 0.06 0 0"
                  size="0.014" rgba="0.20 0.20 0.90 1"/>

            <!-- Pen slide (z) -->
            <body name="pen" pos="0.06 0 0">
              <joint name="pen_z" type="slide" axis="0 0 1" damping="8"
                     limited="true" range="-0.02 0.05"/>

              <geom name="pen_body" type="cylinder" size="0.006 0.055"
                    pos="0 0 -0.055" rgba="0.07 0.07 0.07 1"/>

              <!-- Tip sphere (non-colliding) -->
              <geom name="pen_tip" type="sphere" size="0.003"
                    pos="0 0 -0.11" rgba="0 0 0 1" contype="0" conaffinity="0"/>

              <site name="pen_tip_site" pos="0 0 -0.11" size="0.004" rgba="0 0.3 1 1"/>
            </body>
          </body>
        </body>
      </body>
    </body>
  </worldbody>

  <!-- Home pose (qpos) -->
  <keyframe>
    <key name="home" qpos="0 0.8 -0.8 0.03"/>
  </keyframe>
</mujoco>
